Workbook

Sheet Dashboard
A1: M M Forgings Ltd — Independent Credit Rating Analysis
A2: NSE: MMFL | BSE: 522241 | Consolidated | Actual public data (Screener.in, CARE Ratings) | Prepared by Gaurav Waghmode, 18-Sep-2026
A4: RATING OUTCOME | D4: KEY METRICS (FY26 → FY27E)
A5: Model rating | B5: =Rating!F33 -> BBB | D5: Revenue (₹ Cr) | E5: =TEXT(Analysis!$F$6,"#,##0")&" → "&TEXT(Analysis!$G$6,"#,##0") -> 1,590 → 1,717
A6: CARE rating (Jun-2026) | B6: ="CARE A; Stable" -> CARE A; Stable | D6: PBILDT margin | E6: =TEXT(Analysis!$F$8,"0.0%")&" → "&TEXT(Analysis!$G$8,"0.0%") -> 17.6% → 18.0%
A7: Notch difference (model vs CARE) | B7: =Rating!F36 -> 3 | D7: Gross debt (₹ Cr) | E7: =TEXT(Analysis!$F$15,"#,##0")&" → "&TEXT(Analysis!$G$15,"#,##0") -> 1,235 → 1,175
A8: Weighted score / 10 | B8: =Rating!F32 -> 6.52 | D8: Gearing | E8: =TEXT(Analysis!$F$26,"0.00""x""")&" → "&TEXT(Analysis!$G$26,"0.00""x""") -> 1.27x → 1.12x
A9: Financial sub-score / 10 | B9: =Rating!F31 -> 6.04 | D9: Debt / PBILDT | E9: =TEXT(Analysis!$F$28,"0.00""x""")&" → "&TEXT(Analysis!$G$28,"0.00""x""") -> 4.41x → 3.80x
A10: Indicative PD | B10: =Rating!F34 -> 0.01 | D10: Net debt / PBILDT | E10: =TEXT(Analysis!$F$29,"0.00""x""")&" → "&TEXT(Analysis!$G$29,"0.00""x""") -> 3.61x → 3.07x
A11: Debt basis used | B11: =Rating!C3 -> Gross | D11: Interest coverage | E11: =TEXT(Analysis!$F$30,"0.00""x""")&" → "&TEXT(Analysis!$G$30,"0.00""x""") -> 3.59x → 3.95x
A12: FY27E base-case DSCR | B12: =Debt_Service!G6 -> 1.2290077 | D12: ROCE | E12: =TEXT(Analysis!$F$31,"0.0%")&" → "&TEXT(Analysis!$G$31,"0.0%") -> 9.0% → 9.3%
A13: Worst-scenario DSCR | B13: =Debt_Service!G9 -> 0.88594776 | D13: Cash accruals (₹ Cr) | E13: =TEXT(Analysis!$F$14,"#,##0")&" → "&TEXT(Analysis!$G$14,"#,##0") -> 202 → 215
A14: PBILDT cushion before accruals < repayment | B14: =Debt_Service!G13 -> 0.23543171
A17: Chart data (linked)
A18: Year | B18: FY22 | C18: FY23 | D18: FY24 | E18: FY25 | F18: FY26 | G18: FY27E
A19: Gross debt (₹ Cr) | B19: =Analysis!$B$15 -> 685 | C19: =Analysis!$C$15 -> 756 | D19: =Analysis!$D$15 -> 931 | E19: =Analysis!$E$15 -> 1185 | F19: =Analysis!$F$15 -> 1235 | G19: =Analysis!$G$15 -> 1175
A20: PBILDT (₹ Cr) | B20: =Analysis!$B$7 -> 209 | C20: =Analysis!$C$7 -> 273 | D20: =Analysis!$D$7 -> 293 | E20: =Analysis!$E$7 -> 296 | F20: =Analysis!$F$7 -> 280 | G20: =Analysis!$G$7 -> 309.096
A21: Debt / PBILDT (x) | B21: =Analysis!$B$28 -> 3.277512 | C21: =Analysis!$C$28 -> 2.7692308 | D21: =Analysis!$D$28 -> 3.1774744 | E21: =Analysis!$E$28 -> 4.0033784 | F21: =Analysis!$F$28 -> 4.4107143 | G21: =Analysis!$G$28 -> 3.801408
A22: Gearing (x) | B22: =Analysis!$B$26 -> 1.2254025 | C22: =Analysis!$C$26 -> 1.1233284 | D22: =Analysis!$D$26 -> 1.1799747 | E22: =Analysis!$E$26 -> 1.3269877 | F22: =Analysis!$F$26 -> 1.2666667 | G22: =Analysis!$G$26 -> 1.1173681
A40: Sources: Screener.in consolidated financials (C-MOTS data) and CARE Ratings press release dated 30-Jun-2026. Independent analysis for educational purposes; not investment advice or an official rating.

Sheet Source_Data
A1: M M Forgings Ltd (NSE: MMFL / BSE: 522241) — Source Data
A2: Consolidated, ₹ crore, fiscal years ending 31 March. Blue = sourced input. Column H cites the source for each row.
A4: ₹ crore | B4: FY22 | C4: FY23 | D4: FY24 | E4: FY25 | F4: FY26 | H4: Source
A5: PROFIT & LOSS
A6: Sales / total operating income | B6: 1140 | C6: 1462 | D6: 1563 | E6: 1525 | F6: 1590 | H6: Screener.in consolidated (data: C-MOTS), accessed 18-Sep-2026
A7: Operating expenses | B7: 931 | C7: 1189 | D7: 1270 | E7: 1229 | F7: 1310 | H7: Screener.in consolidated (data: C-MOTS), accessed 18-Sep-2026
A8: Other income | B8: 16 | C8: 12 | D8: 22 | E8: 23 | F8: 16 | H8: Screener.in consolidated (data: C-MOTS), accessed 18-Sep-2026
A9: Interest (finance cost) | B9: 28 | C9: 30 | D9: 42 | E9: 60 | F9: 78 | H9: Screener.in consolidated (data: C-MOTS), accessed 18-Sep-2026
A10: Depreciation | B10: 68 | C10: 79 | D10: 83 | E10: 93 | F10: 103 | H10: Screener.in consolidated (data: C-MOTS), accessed 18-Sep-2026
A11: Profit before tax | B11: 129 | C11: 177 | D11: 189 | E11: 166 | F11: 115 | H11: Screener.in consolidated (data: C-MOTS), accessed 18-Sep-2026
A12: Net profit (PAT) | B12: 91 | C12: 128 | D12: 135 | E12: 123 | F12: 99 | H12: Screener.in consolidated (data: C-MOTS), accessed 18-Sep-2026
A13: Dividend payout % | B13: 0.16 | C13: 0.11 | D13: 0.14 | E13: 0.16 | F13: 0.2 | H13: Screener.in consolidated (data: C-MOTS), accessed 18-Sep-2026
A14: BALANCE SHEET (31 March)
A15: Equity share capital | B15: 24 | C15: 24 | D15: 24 | E15: 48 | F15: 48 | H15: Screener.in consolidated (data: C-MOTS), accessed 18-Sep-2026
A16: Reserves | B16: 535 | C16: 649 | D16: 765 | E16: 845 | F16: 927 | H16: Screener.in consolidated (data: C-MOTS), accessed 18-Sep-2026
A17: Borrowings (gross) | B17: 685 | C17: 756 | D17: 931 | E17: 1185 | F17: 1235 | H17: Screener.in consolidated (data: C-MOTS), accessed 18-Sep-2026
A18: Other liabilities | B18: 170 | C18: 232 | D18: 249 | E18: 271 | F18: 286 | H18: Screener.in consolidated (data: C-MOTS), accessed 18-Sep-2026
A19: Net fixed assets | B19: 708 | C19: 804 | D19: 914 | E19: 964 | F19: 1101 | H19: Screener.in consolidated (data: C-MOTS), accessed 18-Sep-2026
A20: Capital work-in-progress | B20: 36 | C20: 63 | D20: 124 | E20: 383 | F20: 335 | H20: Screener.in consolidated (data: C-MOTS), accessed 18-Sep-2026
A21: Investments (non-current, per Screener) | B21: 22 | C21: 22 | D21: 23 | E21: 4 | F21: 10 | H21: Screener.in consolidated (data: C-MOTS), accessed 18-Sep-2026
A22: Other assets (current assets etc.) | B22: 647 | C22: 772 | D22: 908 | E22: 998 | F22: 1051 | H22: Screener.in consolidated (data: C-MOTS), accessed 18-Sep-2026
A23: CASH FLOW
A24: Cash from operating activity | B24: 150 | C24: 160 | D24: 149 | E24: 182 | F24: 228 | H24: Screener.in consolidated (data: C-MOTS), accessed 18-Sep-2026
A25: Cash from investing activity | B25: -126 | C25: -187 | D25: -232 | E25: -358 | F25: -182 | H25: Screener.in consolidated (data: C-MOTS), accessed 18-Sep-2026
A26: Cash from financing activity | B26: 14 | C26: 16 | D26: 77 | E26: 185 | F26: -38 | H26: Screener.in consolidated (data: C-MOTS), accessed 18-Sep-2026
A27: WORKING-CAPITAL DAYS
A28: Debtor days | B28: 50 | C28: 49 | D28: 64 | E28: 85 | F28: 96 | H28: Screener.in consolidated (data: C-MOTS), accessed 18-Sep-2026
A29: Inventory days | B29: 147 | C29: 163 | D29: 176 | E29: 188 | F29: 171 | H29: Screener.in consolidated (data: C-MOTS), accessed 18-Sep-2026
A30: Days payable | B30: 79 | C30: 89 | D30: 82 | E30: 95 | F30: 103 | H30: Screener.in consolidated (data: C-MOTS), accessed 18-Sep-2026
A32: CARE RATINGS — PUBLISHED FIGURES & DISCLOSURES (press release 30-Jun-2026)
A33: Total operating income (CARE) | D33: 1563.07 | E33: 1525.18 | F33: 1589.87 | H33: CARE Ratings press release, M M Forgings Ltd, 30-Jun-2026
A34: PBILDT (CARE) | D34: 292.83 | E34: 296.08 | F34: 279.98 | H34: CARE Ratings press release, M M Forgings Ltd, 30-Jun-2026
A35: PAT (CARE) | D35: 135.04 | E35: 121.86 | F35: 98.67 | H35: CARE Ratings press release, M M Forgings Ltd, 30-Jun-2026
A36: Overall gearing (CARE) | D36: 1.18 | E36: 1.33 | F36: 1.1 | H36: CARE Ratings press release, M M Forgings Ltd, 30-Jun-2026
A37: Interest coverage (CARE table) | D37: 6.92 | E37: 4.95 | F37: 3.58 | H37: CARE Ratings press release, M M Forgings Ltd, 30-Jun-2026
A38: Liquid investments + cash & bank | E38: 218 | F38: 225 | H38: CARE Ratings press release, M M Forgings Ltd, 30-Jun-2026
A39: Total debt / PBILDT (CARE text) | E39: 4 | F39: 3.84 | H39: CARE Ratings press release, M M Forgings Ltd, 30-Jun-2026
A40: ROCE (CARE text) | E40: 0.1162 | F40: 0.0916 | H40: CARE Ratings press release, M M Forgings Ltd, 30-Jun-2026
A41: Term-debt repayment p.a., next 3 yrs — low (₹ Cr) | F41: 150 | H41: CARE Ratings press release, M M Forgings Ltd, 30-Jun-2026
A42: Term-debt repayment p.a., next 3 yrs — high (₹ Cr) | F42: 170 | H42: CARE Ratings press release, M M Forgings Ltd, 30-Jun-2026
...

Sheet FY27E_Base
A1: FY27E Base Case (analyst estimate)
A2: Forward view used alongside FY26 actuals, as rating agencies rate on expected performance. Every assumption is blue and justified.
A3: Assumption | B3: Value | C3: Rationale
A4: Revenue growth FY27E | B4: 0.08 | C4: Q1FY27 sales +16% YoY (₹420 Cr vs ₹362 Cr); haircut to 8% for CV cyclicality and US tariff uncertainty
A5: PBILDT margin FY27E | B5: 0.18 | C5: Q4FY26 18.9%, Q1FY27 17.9%; CARE: margin recovery expected as new presses ramp up
A6: Other income (recurring) ₹ Cr | B6: 16 | C6: FY26 level; excludes the ₹63 Cr Q1FY27 one-off
A7: Depreciation ₹ Cr | B7: 118 | C7: Q1FY27 run-rate ₹30 Cr/qtr less ramp
A8: Average cost of debt | B8: 0.065 | C8: FY26 interest ₹78 Cr / avg debt ₹1,210 Cr = 6.4%
A9: Term-debt repayment FY27E ₹ Cr | B9: 160 | C9: Mid-point of CARE-disclosed ₹150–170 Cr
A10: New debt drawn FY27E ₹ Cr | B10: 100 | C10: Part-funding of ₹230 Cr 16,500T press (company); CARE: new debt capex aligned to repayments
A11: Tax rate | B11: 0.25 | C11: Normalised; FY26 14% was below normal
A12: Dividend ₹ Cr | B12: 20 | C12: FY26 payout ~20% of PAT

Sheet Analysis
A1: Financial Statement & Ratio Analysis
A2: FY22–FY26 actual (linked, green) + FY27E base case. Ratios use CARE definitions where stated (PBILDT = operating profit before other income).
A4: ₹ crore | B4: FY22 | C4: FY23 | D4: FY24 | E4: FY25 | F4: FY26 | G4: FY27E
A5: PROFIT & LOSS AND CASH ACCRUALS
A6: Total operating income | B6: =Source_Data!B6 -> 1140 | C6: =Source_Data!C6 -> 1462 | D6: =Source_Data!D6 -> 1563 | E6: =Source_Data!E6 -> 1525 | F6: =Source_Data!F6 -> 1590 | G6: =F6*(1+FY27E_Base!$B$4) -> 1717.2
A7: PBILDT (operating profit) | B7: =Source_Data!B6-Source_Data!B7 -> 209 | C7: =Source_Data!C6-Source_Data!C7 -> 273 | D7: =Source_Data!D6-Source_Data!D7 -> 293 | E7: =Source_Data!E6-Source_Data!E7 -> 296 | F7: =Source_Data!F6-Source_Data!F7 -> 280 | G7: =G6*FY27E_Base!$B$5 -> 309.096
A8: PBILDT margin | B8: =B7/B6 -> 0.18333333 | C8: =C7/C6 -> 0.18673051 | D8: =D7/D6 -> 0.18746001 | E8: =E7/E6 -> 0.19409836 | F8: =F7/F6 -> 0.17610063 | G8: =G7/G6 -> 0.18
A9: Other income | B9: =Source_Data!B8 -> 16 | C9: =Source_Data!C8 -> 12 | D9: =Source_Data!D8 -> 22 | E9: =Source_Data!E8 -> 23 | F9: =Source_Data!F8 -> 16 | G9: =FY27E_Base!$B$6 -> 16
A10: Interest | B10: =Source_Data!B9 -> 28 | C10: =Source_Data!C9 -> 30 | D10: =Source_Data!D9 -> 42 | E10: =Source_Data!E9 -> 60 | F10: =Source_Data!F9 -> 78 | G10: =AVERAGE(F15,G15)*FY27E_Base!$B$8 -> 78.325
A11: Depreciation | B11: =Source_Data!B10 -> 68 | C11: =Source_Data!C10 -> 79 | D11: =Source_Data!D10 -> 83 | E11: =Source_Data!E10 -> 93 | F11: =Source_Data!F10 -> 103 | G11: =FY27E_Base!$B$7 -> 118
A12: PBT | B12: =B7+B9-B10-B11 -> 129 | C12: =C7+C9-C10-C11 -> 176 | D12: =D7+D9-D10-D11 -> 190 | E12: =E7+E9-E10-E11 -> 166 | F12: =F7+F9-F10-F11 -> 115 | G12: =G7+G9-G10-G11 -> 128.771
A13: PAT | B13: =Source_Data!B12 -> 91 | C13: =Source_Data!C12 -> 128 | D13: =Source_Data!D12 -> 135 | E13: =Source_Data!E12 -> 123 | F13: =Source_Data!F12 -> 99 | G13: =G12*(1-FY27E_Base!$B$11) -> 96.57825
A14: Gross cash accruals (PAT + depreciation) | B14: =B13+B11 -> 159 | C14: =C13+C11 -> 207 | D14: =D13+D11 -> 218 | E14: =E13+E11 -> 216 | F14: =F13+F11 -> 202 | G14: =G13+G11 -> 214.57825
A15: Gross debt (closing) | B15: =Source_Data!B17 -> 685 | C15: =Source_Data!C17 -> 756 | D15: =Source_Data!D17 -> 931 | E15: =Source_Data!E17 -> 1185 | F15: =Source_Data!F17 -> 1235 | G15: =F15-FY27E_Base!$B$9+FY27E_Base!$B$10 -> 1175
A16: Net worth (equity + reserves) | B16: =Source_Data!B15+Source_Data!B16 -> 559 | C16: =Source_Data!C15+Source_Data!C16 -> 673 | D16: =Source_Data!D15+Source_Data!D16 -> 789 | E16: =Source_Data!E15+Source_Data!E16 -> 893 | F16: =Source_Data!F15+Source_Data!F16 -> 975 | G16: =F16+G13-FY27E_Base!$B$12 -> 1051.5783
A17: Liquid investments + cash (CARE) | B17: =0 -> 0 | C17: =0 -> 0 | D17: =0 -> 0 | E17: =Source_Data!E38 -> 218 | F17: =Source_Data!F38 -> 225 | G17: =F17 -> 225
A18: Net debt | B18: =B15-B17 -> 685 | C18: =C15-C17 -> 756 | D18: =D15-D17 -> 931 | E18: =E15-E17 -> 967 | F18: =F15-F17 -> 1010 | G18: =G15-G17 -> 950
A19: Capital employed (net worth + debt) | B19: =B16+B15 -> 1244 | C19: =C16+C15 -> 1429 | D19: =D16+D15 -> 1720 | E19: =E16+E15 -> 2078 | F19: =F16+F15 -> 2210 | G19: =G16+G15 -> 2226.5783
A20: Cash from operations | B20: =Source_Data!B24 -> 150 | C20: =Source_Data!C24 -> 160 | D20: =Source_Data!D24 -> 149 | E20: =Source_Data!E24 -> 182 | F20: =Source_Data!F24 -> 228
A21: Capex (CFI, proxy) | B21: =-Source_Data!B25 -> 126 | C21: =-Source_Data!C25 -> 187 | D21: =-Source_Data!D25 -> 232 | E21: =-Source_Data!E25 -> 358 | F21: =-Source_Data!F25 -> 182
A22: Free cash flow (CFO − capex) | B22: =B20-B21 -> 24 | C22: =C20-C21 -> -27 | D22: =D20-D21 -> -83 | E22: =E20-E21 -> -176 | F22: =F20-F21 -> 46
A24: KEY CREDIT RATIOS
A25: Revenue growth | C25: =C6/B6-1 -> 0.28245614 | D25: =D6/C6-1 -> 0.069083447 | E25: =E6/D6-1 -> -0.02431222 | F25: =F6/E6-1 -> 0.042622951 | G25: =G6/F6-1 -> 0.08
A26: Overall gearing (gross debt / net worth) | B26: =B15/B16 -> 1.2254025 | C26: =C15/C16 -> 1.1233284 | D26: =D15/D16 -> 1.1799747 | E26: =E15/E16 -> 1.3269877 | F26: =F15/F16 -> 1.2666667 | G26: =G15/G16 -> 1.1173681
A27: Net gearing | B27: =B18/B16 -> 1.2254025 | C27: =C18/C16 -> 1.1233284 | D27: =D18/D16 -> 1.1799747 | E27: =E18/E16 -> 1.0828667 | F27: =F18/F16 -> 1.0358974 | G27: =G18/G16 -> 0.903404
A28: Total debt / PBILDT | B28: =B15/B7 -> 3.277512 | C28: =C15/C7 -> 2.7692308 | D28: =D15/D7 -> 3.1774744 | E28: =E15/E7 -> 4.0033784 | F28: =F15/F7 -> 4.4107143 | G28: =G15/G7 -> 3.801408
A29: Net debt / PBILDT | B29: =B18/B7 -> 3.277512 | C29: =C18/C7 -> 2.7692308 | D29: =D18/D7 -> 3.1774744 | E29: =E18/E7 -> 3.2668919 | F29: =F18/F7 -> 3.6071429 | G29: =G18/G7 -> 3.0734788
A30: Interest coverage (PBILDT / interest) | B30: =B7/B10 -> 7.4642857 | C30: =C7/C10 -> 9.1 | D30: =D7/D10 -> 6.9761905 | E30: =E7/E10 -> 4.9333333 | F30: =F7/F10 -> 3.5897436 | G30: =G7/G10 -> 3.9463262
A31: ROCE (PBIT / avg capital employed) | C31: =(C12+C10)/AVERAGE(C19,B19) -> 0.15413393 | D31: =(D12+D10)/AVERAGE(D19,C19) -> 0.14734836 | E31: =(E12+E10)/AVERAGE(E19,D19) -> 0.11901001 | F31: =(F12+F10)/AVERAGE(F19,E19) -> 0.090018657 | G31: =(G12+G10)/AVERAGE(G19,F19) -> 0.093358435
A32: ROE (PAT / avg net worth) | C32: =C13/AVERAGE(C16,B16) -> 0.20779221 | D32: =D13/AVERAGE(D16,C16) -> 0.18467852 | E32: =E13/AVERAGE(E16,D16) -> 0.14625446 | F32: =F13/AVERAGE(F16,E16) -> 0.10599572 | G32: =G13/AVERAGE(G16,F16) -> 0.095311642
A33: CFO / PBILDT (cash conversion) | B33: =B20/B7 -> 0.71770335 | C33: =C20/C7 -> 0.58608059 | D33: =D20/D7 -> 0.50853242 | E33: =E20/E7 -> 0.61486486 | F33: =F20/F7 -> 0.81428571
A34: Total debt / CFO (years) | B34: =B15/B20 -> 4.5666667 | C34: =C15/C20 -> 4.725 | D34: =D15/D20 -> 6.2483221 | E34: =E15/E20 -> 6.510989 | F34: =F15/F20 -> 5.4166667
A35: Cash conversion cycle (days) | B35: =Source_Data!B28+Source_Data!B29-Source_Data!B30 -> 118 | C35: =Source_Data!C28+Source_Data!C29-Source_Data!C30 -> 123 | D35: =Source_Data!D28+Source_Data!D29-Source_Data!D30 -> 158 | E35: =Source_Data!E28+Source_Data!E29-Source_Data!E30 -> 178 | F35: =Source_Data!F28+Source_Data!F29-Source_Data!F30 -> 164
A36: Asset turnover (sales / (NFA + CWIP)) | B36: =B6/(Source_Data!B19+Source_Data!B20) -> 1.5322581 | C36: =C6/(Source_Data!C19+Source_Data!C20) -> 1.6862745 | D36: =D6/(Source_Data!D19+Source_Data!D20) -> 1.5057803 | E36: =E6/(Source_Data!E19+Source_Data!E20) -> 1.1321455 | F36: =F6/(Source_Data!F19+Source_Data!F20) -> 1.1072423
A37: CWIP as % of gross block proxy (NFA + CWIP) | B37: =Source_Data!B20/(Source_Data!B19+Source_Data!B20) -> 0.048387097 | C37: =Source_Data!C20/(Source_Data!C19+Source_Data!C20) -> 0.07266436 | D37: =Source_Data!D20/(Source_Data!D19+Source_Data!D20) -> 0.1194605 | E37: =Source_Data!E20/(Source_Data!E19+Source_Data!E20) -> 0.28433556 | F37: =Source_Data!F20/(Source_Data!F19+Source_Data!F20) -> 0.23328691
A39: Summary metrics
A40: Revenue CAGR FY23–FY26 | C40: =(F6/C6)^(1/3)-1 -> 0.028371228
A41: PBILDT CAGR FY23–FY26 | C41: =(F7/C7)^(1/3)-1 -> 0.0084749803
A42: Debt added FY23–FY26 (₹ Cr) | C42: =F15-C15 -> 479
A43: PBILDT added FY23–FY26 (₹ Cr) | C43: =F7-C7 -> 7
...

Sheet Debt_Service
A1: Debt-Service Capacity — FY27E
A2: Can cash accruals meet ₹150–170 Cr of annual term-debt repayment? Tested with and without the liquid-investment cushion.
A4: Scenario | B4: PBILDT | C4: Interest | D4: Tax | E4: Cash accruals | F4: Repayment | G4: DSCR | H4: Accruals / repayment | I4: Liquid cover*
A5: FY26 actual, mid repayment | B5: =Analysis!$F$7 -> 280 | C5: =Analysis!$F$10 -> 78 | D5: =MAX(0,B5+FY27E_Base!$B$6-C5-FY27E_Base!$B$7)*FY27E_Base!$B$11 -> 25 | E5: =B5+FY27E_Base!$B$6-C5-D5 -> 193 | F5: =Source_Data!$F$41/2+Source_Data!$F$42/2 -> 160 | G5: =(E5+C5)/(C5+F5) -> 1.1386555 | H5: =E5/F5 -> 1.20625 | I5: =(E5+Analysis!$F$17)/F5 -> 2.6125
A6: FY27E base case | B6: =Analysis!$G$7 -> 309.096 | C6: =Analysis!$G$10 -> 78.325 | D6: =MAX(0,B6+FY27E_Base!$B$6-C6-FY27E_Base!$B$7)*FY27E_Base!$B$11 -> 32.19275 | E6: =B6+FY27E_Base!$B$6-C6-D6 -> 214.57825 | F6: =FY27E_Base!$B$9 -> 160 | G6: =(E6+C6)/(C6+F6) -> 1.2290077 | H6: =E6/F6 -> 1.3411141 | I6: =(E6+Analysis!$F$17)/F6 -> 2.7473641
A7: FY27E: PBILDT −15% (CV downturn) | B7: =Analysis!$G$7*0.85 -> 262.7316 | C7: =Analysis!$G$10 -> 78.325 | D7: =MAX(0,B7+FY27E_Base!$B$6-C7-FY27E_Base!$B$7)*FY27E_Base!$B$11 -> 20.60165 | E7: =B7+FY27E_Base!$B$6-C7-D7 -> 179.80495 | F7: =FY27E_Base!$B$9 -> 160 | G7: =(E7+C7)/(C7+F7) -> 1.0831006 | H7: =E7/F7 -> 1.1237809 | I7: =(E7+Analysis!$F$17)/F7 -> 2.5300309
A8: FY27E: PBILDT −25%, repayment at high end | B8: =Analysis!$G$7*0.75 -> 231.822 | C8: =Analysis!$G$10 -> 78.325 | D8: =MAX(0,B8+FY27E_Base!$B$6-C8-FY27E_Base!$B$7)*FY27E_Base!$B$11 -> 12.87425 | E8: =B8+FY27E_Base!$B$6-C8-D8 -> 156.62275 | F8: =Source_Data!$F$42 -> 170 | G8: =(E8+C8)/(C8+F8) -> 0.94613007 | H8: =E8/F8 -> 0.92131029 | I8: =(E8+Analysis!$F$17)/F8 -> 2.2448397
A9: FY27E: PBILDT −25%, rates +200 bps, high repayment | B9: =Analysis!$G$7*0.75 -> 231.822 | C9: =Analysis!$G$10+0.02*Analysis!$G$15 -> 101.825 | D9: =MAX(0,B9+FY27E_Base!$B$6-C9-FY27E_Base!$B$7)*FY27E_Base!$B$11 -> 6.99925 | E9: =B9+FY27E_Base!$B$6-C9-D9 -> 138.99775 | F9: =Source_Data!$F$42 -> 170 | G9: =(E9+C9)/(C9+F9) -> 0.88594776 | H9: =E9/F9 -> 0.81763382 | I9: =(E9+Analysis!$F$17)/F9 -> 2.1411632
A11: * Liquid cover = (cash accruals + ₹225 Cr liquid investments & cash) / repayment. DSCR here = (cash accruals + interest) / (interest + repayment), using all interest incl. working-capital interest — conservative.
A13: PBILDT decline that takes accruals/repayment to 1.0x (FY27E, pre-tax approx.) | G13: =((E6-F6)/(1-FY27E_Base!$B$11))/B6 -> 0.23543171

Sheet Rating
A1: Credit Rating Scorecard — M M Forgings
A2: Same hybrid methodology as the SVF case, recalibrated for a listed mid-corporate. Financial metrics blend FY26 actual (60%) and FY27E base (40%).
A3: Debt basis for leverage metrics (Gross / Net) | C3: Gross | G3: Gross = conservative bank view; Net credits ₹225 Cr liquid investments (CARE's liquidity view)
A4: Weight on FY26 actual (rest on FY27E) | C4: 0.6
A6: Parameter | B6: Weight | C6: FY26 | D6: FY27E | E6: Blend | F6: Score | G6: Rationale
A7: A. FINANCIAL RISK (50%)
A8: Debt / PBILDT | B8: 0.1 | C8: =IF($C$3="Net",Analysis!$F$29,Analysis!$F$28) -> 4.4107143 | D8: =IF($C$3="Net",Analysis!$G$29,Analysis!$G$28) -> 3.801408 | E8: =$C$4*C8+(1-$C$4)*D8 -> 4.1669918 | F8: =INDEX($J$41:$Q$41,MATCH(E8,$J$40:$Q$40,1)) -> 5 | G8: CARE upgrade trigger < 3.0x
A9: Overall gearing | B9: 0.08 | C9: =IF($C$3="Net",Analysis!$F$27,Analysis!$F$26) -> 1.2666667 | D9: =IF($C$3="Net",Analysis!$G$27,Analysis!$G$26) -> 1.1173681 | E9: =$C$4*C9+(1-$C$4)*D9 -> 1.2069472 | F9: =INDEX($J$44:$Q$44,MATCH(E9,$J$43:$Q$43,1)) -> 6 | G9: CARE: upgrade < 0.8x; downgrade > 1.5x
A10: Interest coverage (PBILDT / interest) | B10: 0.07 | C10: =Analysis!$F$30 -> 3.5897436 | D10: =Analysis!$G$30 -> 3.9463262 | E10: =$C$4*C10+(1-$C$4)*D10 -> 3.7323766 | F10: =INDEX($J$47:$Q$47,MATCH(E10,$J$46:$Q$46,1)) -> 8 | G10: Fell from 6.9x (FY24) as debt-funded capex raised interest
A11: Cash accruals / term-debt repayment | B11: 0.08 | C11: =Analysis!$F$14/(Source_Data!$F$41/2+Source_Data!$F$42/2) -> 1.2625 | D11: =Analysis!$G$14/FY27E_Base!$B$9 -> 1.3411141 | E11: =$C$4*C11+(1-$C$4)*D11 -> 1.2939456 | F11: =INDEX($J$50:$Q$50,MATCH(E11,$J$49:$Q$49,1)) -> 5 | G11: Repayment ₹150–170 Cr p.a. (CARE)
A12: ROCE | B12: 0.06 | C12: =Analysis!$F$31 -> 0.090018657 | D12: =Analysis!$G$31 -> 0.093358435 | E12: =$C$4*C12+(1-$C$4)*D12 -> 0.091354568 | F12: =INDEX($J$53:$Q$53,MATCH(E12,$J$52:$Q$52,1)) -> 4 | G12: Depressed by ₹335 Cr CWIP not yet earning
A13: PBILDT margin | B13: 0.04 | C13: =Analysis!$F$8 -> 0.17610063 | D13: =Analysis!$G$8 -> 0.18 | E13: =$C$4*C13+(1-$C$4)*D13 -> 0.17766038 | F13: =INDEX($J$56:$Q$56,MATCH(E13,$J$55:$Q$55,1)) -> 8 | G13: Range-bound 17.6–19.4%
A14: Operating scale (revenue ₹ Cr) | B14: 0.04 | C14: =Analysis!$F$6 -> 1590 | D14: =Analysis!$G$6 -> 1717.2 | E14: =$C$4*C14+(1-$C$4)*D14 -> 1640.88 | F14: =INDEX($J$59:$Q$59,MATCH(E14,$J$58:$Q$58,1)) -> 7 | G14: Scale supports absorption of fixed costs
A15: Cash conversion (CFO / PBILDT) | B15: 0.03 | C15: =Analysis!$F$33 -> 0.81428571 | D15: =Analysis!$F$33 -> 0.81428571 | E15: =$C$4*C15+(1-$C$4)*D15 -> 0.81428571 | F15: =INDEX($J$62:$Q$62,MATCH(E15,$J$61:$Q$61,1)) -> 8 | G15: FY26 actual used for both columns
A16: B. BUSINESS RISK (25%)
A17: Track record & market position | B17: 0.05 | F17: 9 | G17: Forging since 1974; two-decade client relationships; 130,000 MTPA capacity
A18: Product & geographic diversity | B18: 0.05 | F18: 8 | G18: 0.1–120 kg parts; ~35% exports (US 10%, Europe 20%)
A19: Customer concentration | B19: 0.05 | F19: 5 | G19: Top-10 = 62% of TOI (9MFY26), down from 69%
A20: End-market cyclicality | B20: 0.05 | F20: 4 | G20: ~76% commercial vehicles — the most cyclical auto segment
A21: Raw-material & tariff exposure | B21: 0.05 | F21: 6 | G21: Pass-through clauses with lag; US tariff hit volumes in Q2–Q3 FY26
A22: C. MANAGEMENT & GOVERNANCE (10%)
A23: Promoter experience & commitment | B23: 0.05 | F23: 8 | G23: Second-generation MD (IIT Madras), 25+ yrs; promoter holding 56.3%, no pledge
A24: Governance & disclosure | B24: 0.05 | F24: 7 | G24: Listed; independent directors; regular concalls. CARE text/table ICR mismatch noted
A25: D. LIQUIDITY & FINANCIAL FLEXIBILITY (15%)
A26: Liquid investments & cash | B26: 0.05 | F26: 8 | G26: ₹225 Cr (Mar-26) ≈ 1.4x one year's repayment
A27: Working-capital headroom | B27: 0.05 | F27: 7 | G27: Fund-based utilisation ~80% (12m to May-26)
A28: Access to capital | B28: 0.05 | F28: 8 | G28: Listed, ~₹3,000 Cr market cap; long banking relationships
A30: Total weight (must = 100%) | B30: =SUM(B8:B28) -> 1
A31: Financial sub-score (/10) | F31: =SUMPRODUCT(B8:B15,F8:F15)/SUM(B8:B15) -> 6.04
A32: WEIGHTED SCORE (/10) | F32: =SUMPRODUCT(B8:B28,F8:F28) -> 6.52
A33: MODEL RATING | F33: =INDEX($B$40:$B$52,MATCH(F32,$A$40:$A$52,1)) -> BBB
A34: Indicative 1-yr PD (illustrative) | F34: =INDEX($D$40:$D$52,MATCH(F32,$A$40:$A$52,1)) -> 0.01
A35: CARE rating (30-Jun-2026) | F35: A | G35: CARE A; Stable / CARE A1 — reaffirmed
A36: Notch difference (+ = model more conservative) | F36: =INDEX($C$40:$C$52,MATCH(F33,$B$40:$B$52,0))-INDEX($C$40:$C$52,MATCH(F35,$B$40:$B$52,0)) -> 3
A38: Master scale
A39: Min score | B39: Grade | C39: Rank | D39: PD (illus.) | I39: Threshold grids (breakpoint → score)
A40: 0 | B40: D | C40: 13 | D40: 1 | I40: dpb | J40: 0 | K40: 1 | L40: 1.75 | M40: 2.5 | N40: 3 | O40: 3.5 | P40: 4.25 | Q40: 5.5
A41: 3 | B41: C | C41: 12 | D41: 0.25 | J41: 10 | K41: 9 | L41: 8 | M41: 7 | N41: 6 | O41: 5 | P41: 3 | Q41: 1
A42: 4 | B42: B | C42: 11 | D42: 0.1
A43: 4.6 | B43: BB- | C43: 10 | D43: 0.05 | I43: gear | J43: 0 | K43: 0.25 | L43: 0.5 | M43: 0.8 | N43: 1 | O43: 1.25 | P43: 1.5 | Q43: 2.5
...

Sheet Rating_Bridge
A1: Notch Bridge — Model Rating to CARE Rating
A2: Values produced by python/rating_bridge.py, which replicates the Rating sheet in Python (step 1 reproduces the sheet's score exactly) and applies each adjustment cumulatively.
A4: Cumulative adjustment | B4: Score /10 | C4: Grade
A5: Model as built (gross debt, 60% FY26 / 40% FY27E) | B5: 6.52 | C5: BBB
A6: + Net off ₹225 Cr liquid investments | B6: 6.7 | C6: BBB+
A7: + Adopt CARE's narrower debt definition (~₹160 Cr lower) | B7: 6.8 | C7: BBB+
A8: + Rate purely on FY27E (forward-looking, as CRAs do) | B8: 6.92 | C8: BBB+
A9: + Use CARE's envisaged accruals (mid-point ₹290 Cr) | B9: 7.08 | C9: A-
A11: CARE rating (30-Jun-2026) | C11: A
A12: Check: step 1 equals Rating sheet score | B12: =IF(ABS(B5-Rating!F32)<0.005,"OK","MISMATCH") -> OK
A14: Reading: even after crediting liquidity, CARE's debt definition and CARE's own accrual expectation, the scorecard reaches A-, one notch below CARE's A.
A15: The residual notch reflects weight CARE places on 50-year track record, scale and management's capex-completion guidance that an outside analyst cannot verify.
A16: Analyst view: CARE A is defensible but has limited headroom. It depends on accruals rising to ~₹290 Cr; FY26 accruals were ₹202 Cr.

Sheet CARE_Benchmark
A1: Benchmarking Against CARE Ratings
A2: Reconciles our computed figures to CARE's published numbers and measures the distance to CARE's stated upgrade / downgrade triggers.
A4: Metric (FY26) | B4: Our figure | C4: CARE figure | D4: Difference | E4: Status | F4: Comment
A5: Total operating income | B5: =Analysis!$F$6 -> 1590 | C5: =Source_Data!F33 -> 1589.87 | D5: =B5-C5 -> 0.13 | E5: =IF(ABS(D5)<=0.03*ABS(C5),"Reconciles","Investigate") -> Reconciles | F5: Screener rounds to ₹ Cr
A6: PBILDT | B6: =Analysis!$F$7 -> 280 | C6: =Source_Data!F34 -> 279.98 | D6: =B6-C6 -> 0.02 | E6: =IF(ABS(D6)<=0.03*ABS(C6),"Reconciles","Investigate") -> Reconciles
A7: PAT | B7: =Analysis!$F$13 -> 99 | C7: =Source_Data!F35 -> 98.67 | D7: =B7-C7 -> 0.33 | E7: =IF(ABS(D7)<=0.03*ABS(C7),"Reconciles","Investigate") -> Reconciles
A8: Interest coverage | B8: =Analysis!$F$30 -> 3.5897436 | C8: =Source_Data!F37 -> 3.58 | D8: =B8-C8 -> 0.0097435897 | E8: =IF(ABS(D8)<=0.03*ABS(C8),"Reconciles","Investigate") -> Reconciles | F8: CARE's own text quotes 3.98x vs 3.58x in its table — the table reconciles to PBILDT/interest
A9: Overall gearing | B9: =Analysis!$F$26 -> 1.2666667 | C9: =Source_Data!F36 -> 1.1 | D9: =B9-C9 -> 0.16666667 | E9: =IF(ABS(D9)<=0.03*ABS(C9),"Reconciles","Investigate") -> Investigate | F9: FY24–FY25 reconcile; FY26 gap implies CARE counts ~₹160 Cr less debt (likely classification, e.g. leases/acceptances). We keep the higher, conservative figure
A10: Total debt / PBILDT | B10: =Analysis!$F$28 -> 4.4107143 | C10: =Source_Data!F39 -> 3.84 | D10: =B10-C10 -> 0.57071429 | E10: =IF(ABS(D10)<=0.03*ABS(C10),"Reconciles","Investigate") -> Investigate | F10: Same debt-definition gap as gearing
A11: ROCE | B11: =Analysis!$F$31 -> 0.090018657 | C11: =Source_Data!F40 -> 0.0916 | D11: =B11-C11 -> -0.0015813433 | E11: =IF(ABS(D11)<=0.03*ABS(C11),"Reconciles","Investigate") -> Reconciles | F11: Definitions differ slightly (avg vs closing capital employed)
A12: Implied CARE debt (gearing × our net worth) | B12: =Source_Data!F36*Analysis!$F$16 -> 1072.5
A13: Implied CARE debt (debt/PBILDT × PBILDT) | B13: =Source_Data!F39*Source_Data!F34 -> 1075.1232
A15: CARE trigger | B15: Threshold | C15: FY26 | D15: FY27E | E15: Met? | F15: Distance (FY27E)
A16: Upgrade: gearing below | B16: =Source_Data!$F$52 -> 0.8 | C16: =Analysis!$F$26 -> 1.2666667 | D16: =Analysis!$G$26 -> 1.1173681 | E16: =IF(D16<B16,"Yes","No") -> No | F16: =D16-B16 -> 0.31736811
A17: Upgrade: debt / PBILDT below | B17: =Source_Data!$F$53 -> 3 | C17: =Analysis!$F$28 -> 4.4107143 | D17: =Analysis!$G$28 -> 3.801408 | E17: =IF(D17<B17,"Yes","No") -> No | F17: =D17-B17 -> 0.80140798
A18: Upgrade: ROCE above | B18: =Source_Data!$F$54 -> 0.15 | C18: =Analysis!$F$31 -> 0.090018657 | D18: =Analysis!$G$31 -> 0.093358435 | E18: =IF(D18>B18,"Yes","No") -> No | F18: =D18-B18 -> -0.056641565
A19: Downgrade: gross gearing above | B19: =Source_Data!$F$55 -> 1.5 | C19: =Analysis!$F$26 -> 1.2666667 | D19: =Analysis!$G$26 -> 1.1173681 | E19: =IF(D19>B19,"Yes","No") -> No | F19: =D19-B19 -> -0.38263189
A20: Debt reduction needed for debt/PBILDT < 3.0x at FY27E PBILDT (₹ Cr) | D20: =MAX(0,Analysis!$G$15-Source_Data!$F$53*Analysis!$G$7) -> 247.712
